mplus_output/bi-21-ELSA_W7.out
Mplus VERSION 8.1 (Mac)
MUTHEN & MUTHEN
04/23/2020  10:57 PM

INPUT INSTRUCTIONS

  DATA:
  FILE = "bi-21-ELSA_W7.dat";

  VARIABLE:
  NAMES = mplusid UDAT UDAY UMON UYER UIWR UDWR UANI UBAK USUB UNM1 UNM2 UNM3 UNM4
       UNM5 UHL1 UHL2 UHL3 UHL4 URE2 URE3 URE4 URE5 URE6;
   MISSING=.;
   CATEGORICAL ARE all; idvariable = mplusid;
  ANALYSIS:
  estimator = wlsmv; coverage=0;
  MODEL:
  g by UDAT * ;
   g by UDAY * ;
   g by UMON * ;
   g by UYER * ;
   g by UIWR * ;
   g by UDWR * ;
   g by USUB * ;
   g by UBAK * ;
   g by UNM1 * ;
   g by UNM2 * ;
   g by UNM5 * ;
   g by URE3 * ;
   g by URE5 * ;
   g by URE6 * ;
   g by UANI * ;
   g by URE2 * ;
   g by URE4 * ;
   g by UHL1 * ;
   g by UHL2 * ;
   g by UHL3 * ;
   g by UHL4 * ;
   g by UNM3 * ;
   g by UNM4 * ;
   s1 by UIWR @ 1 ;
   s1 by UDWR @ 1 ;
   g @ 1;
   s1 * ;
   g with s1 @ 0 ;

  OUTPUT:
  standardized; svalues;



*** WARNING
  Data set contains cases with missing on all variables.
  These cases were not included in the analysis.
  Number of cases with missing on all variables:  608
   1 WARNING(S) FOUND IN THE INPUT INSTRUCTIONS




SUMMARY OF ANALYSIS

Number of groups                                                 1
Number of observations                                        9058

Number of dependent variables                                   23
Number of independent variables                                  0
Number of continuous latent variables                            2

Observed dependent variables

  Binary and ordered categorical (ordinal)
   UDAT        UDAY        UMON        UYER        UIWR        UDWR
   UANI        UBAK        USUB        UNM1        UNM2        UNM3
   UNM4        UNM5        UHL1        UHL2        UHL3        UHL4
   URE2        URE3        URE4        URE5        URE6

Continuous latent variables
   G           S1

Variables with special functions

  ID variable           MPLUSID

Estimator                                                    WLSMV
Maximum number of iterations                                  1000
Convergence criterion                                    0.500D-04
Maximum number of steepest descent iterations                   20
Maximum number of iterations for H1                           2000
Convergence criterion for H1                             0.100D-03
Parameterization                                             DELTA
Link                                                        PROBIT

Input data file(s)
  bi-21-ELSA_W7.dat

Input data format  FREE


SUMMARY OF DATA

     Number of missing data patterns           113


COVARIANCE COVERAGE OF DATA

Minimum covariance coverage value   0.000


     PROPORTION OF DATA PRESENT


           Covariance Coverage
              UDAT          UDAY          UMON          UYER          UIWR
              ________      ________      ________      ________      ________
 UDAT           0.985
 UDAY           0.984         0.991
 UMON           0.984         0.990         0.990
 UYER           0.984         0.990         0.990         0.990
 UIWR           0.984         0.990         0.990         0.990         0.998
 UDWR           0.985         0.991         0.990         0.990         0.998
 UANI           0.985         0.991         0.990         0.990         0.998
 UBAK           0.980         0.986         0.986         0.986         0.989
 USUB           0.964         0.969         0.969         0.969         0.971
 UNM1           0.983         0.989         0.989         0.989         0.991
 UNM2           0.975         0.980         0.980         0.980         0.982
 UNM3           0.981         0.987         0.986         0.986         0.988
 UNM4           0.973         0.977         0.977         0.977         0.979
 UNM5           0.969         0.974         0.973         0.974         0.975
 UHL1           0.060         0.060         0.060         0.060         0.060
 UHL2           0.060         0.060         0.060         0.060         0.060
 UHL3           0.060         0.060         0.060         0.060         0.060
 UHL4           0.060         0.060         0.060         0.060         0.060
 URE2           0.060         0.061         0.061         0.061         0.061
 URE3           0.057         0.057         0.057         0.057         0.057
 URE4           0.045         0.045         0.045         0.045         0.045
 URE5           0.044         0.044         0.044         0.044         0.044
 URE6           0.045         0.045         0.045         0.045         0.045


           Covariance Coverage
              UDWR          UANI          UBAK          USUB          UNM1
              ________      ________      ________      ________      ________
 UDWR           1.000
 UANI           1.000         1.000
 UBAK           0.989         0.989         0.989
 USUB           0.971         0.971         0.969         0.971
 UNM1           0.991         0.991         0.987         0.971         0.991
 UNM2           0.982         0.982         0.978         0.963         0.982
 UNM3           0.989         0.989         0.985         0.969         0.989
 UNM4           0.979         0.979         0.975         0.960         0.979
 UNM5           0.975         0.975         0.971         0.957         0.975
 UHL1           0.060         0.060         0.060         0.059         0.060
 UHL2           0.060         0.060         0.060         0.059         0.060
 UHL3           0.060         0.060         0.060         0.059         0.060
 UHL4           0.060         0.060         0.060         0.059         0.060
 URE2           0.061         0.061         0.060         0.060         0.061
 URE3           0.057         0.057         0.057         0.057         0.057
 URE4           0.045         0.045         0.045         0.045         0.045
 URE5           0.044         0.044         0.044         0.044         0.044
 URE6           0.045         0.045         0.045         0.045         0.045


           Covariance Coverage
              UNM2          UNM3          UNM4          UNM5          UHL1
              ________      ________      ________      ________      ________
 UNM2           0.982
 UNM3           0.981         0.989
 UNM4           0.973         0.978         0.979
 UNM5           0.969         0.974         0.969         0.975
 UHL1           0.060         0.060         0.060         0.059         0.060
 UHL2           0.060         0.060         0.060         0.059         0.060
 UHL3           0.060         0.060         0.060         0.059         0.060
 UHL4           0.060         0.060         0.060         0.059         0.060
 URE2           0.061         0.061         0.060         0.059         0.057
 URE3           0.057         0.057         0.057         0.056         0.054
 URE4           0.045         0.045         0.045         0.045         0.043
 URE5           0.044         0.044         0.043         0.043         0.042
 URE6           0.045         0.045         0.044         0.044         0.043


           Covariance Coverage
              UHL2          UHL3          UHL4          URE2          URE3
              ________      ________      ________      ________      ________
 UHL2           0.060
 UHL3           0.060         0.060
 UHL4           0.060         0.060         0.060
 URE2           0.057         0.057         0.057         0.061
 URE3           0.054         0.054         0.054         0.057         0.057
 URE4           0.043         0.043         0.043         0.045         0.044
 URE5           0.042         0.042         0.042         0.044         0.043
 URE6           0.043         0.043         0.043         0.045         0.044


           Covariance Coverage
              URE4          URE5          URE6
              ________      ________      ________
 URE4           0.045
 URE5           0.036         0.044
 URE6           0.037         0.037         0.045


UNIVARIATE PROPORTIONS AND COUNTS FOR CATEGORICAL VARIABLES
